<?xml version="1.0"?>
<robot name="labrobot">
    <!-- ROBOTINO parts -->
    <link name="base_link"/>
    <link name="robotino_base_link">
        <inertial>
          <mass value="20"/>
          <origin xyz="0 0 0"/>
          <inertia ixx="1.0" ixy="0.0" ixz="0.0" iyy="1.0" iyz="0.0" izz="1.0"/>
        </inertial>
        <visual>
          <origin rpy="0 0 1.570795" xyz="0.01 0 0"/>
          <geometry>
            <mesh filename="package://robot_description/meshes/RobotinoBody.dae" scale="0.01 0.01 0.01"/>
          </geometry>
        </visual>
        <collision>
          <origin rpy="0 0 0" xyz="0 0 0.025"/>
          <geometry>
            <cylinder length="0.05" radius="0.18"/>
          </geometry>
        </collision>
      </link>
      <joint name="wheel0_joint" type="continuous">
        <origin rpy="0 0 1.04719666667" xyz="0.065 0.11 0.04"/>
        <axis xyz="-1 0 0"/>
        <parent link="robotino_base_link"/>
        <child link="wheel0_link"/>
      </joint>
      <link name="wheel0_link">
        <inertial>
          <mass value="0.00001"/>
          <origin xyz="0 0 0"/>
          <inertia ixx="1.0" ixy="0.0" ixz="0.0" iyy="1.0" iyz="0.0" izz="1.0"/>
        </inertial>
        <visual>
          <origin rpy="0 0 0" xyz="0 0 0"/>
          <geometry>
            <mesh filename="package://robot_description/meshes/RobotinoWheel.dae" scale="0.01 0.01 0.01"/>
          </geometry>
        </visual>
      </link>
      <joint name="wheel1_joint" type="continuous">
        <origin rpy="0 0 0" xyz="-0.13 0 0.04"/>
        <axis xyz="1 0 0"/>
        <parent link="robotino_base_link"/>
        <child link="wheel1_link"/>
      </joint>
      <link name="wheel1_link">
        <inertial>
          <mass value="0.00001"/>
          <origin xyz="0 0 0"/>
          <inertia ixx="1.0" ixy="0.0" ixz="0.0" iyy="1.0" iyz="0.0" izz="1.0"/>
        </inertial>
        <visual>
          <origin rpy="0 0 0" xyz="0 0 0"/>
          <geometry>
            <mesh filename="package://robot_description/meshes/RobotinoWheel.dae" scale="0.01 0.01 0.01"/>
          </geometry>
        </visual>
      </link>
      <joint name="wheel2_joint" type="continuous">
        <origin rpy="0 0 -1.04719666667" xyz="0.065 -0.11 0.04"/>
        <axis xyz="-1 0 0"/>
        <parent link="robotino_base_link"/>
        <child link="wheel2_link"/>
      </joint>
      <link name="wheel2_link">
        <inertial>
          <mass value="0.00001"/>
          <origin xyz="0 0 0"/>
          <inertia ixx="1.0" ixy="0.0" ixz="0.0" iyy="1.0" iyz="0.0" izz="1.0"/>
        </inertial>
        <visual>
          <origin rpy="0 0 0" xyz="0 0 0"/>
          <geometry>
            <mesh filename="package://robot_description/meshes/RobotinoWheel.dae" scale="0.01 0.01 0.01"/>
          </geometry>
        </visual>
      </link>
      <joint name="command_bridge_joint" type="fixed">
        <origin rpy="0 0 1.570795" xyz="-0.05 0 0.13"/>
        <parent link="robotino_base_link"/>
        <child link="command_bridge_link"/>
      </joint>
      <link name="command_bridge_link">
        <inertial>
          <mass value="0.00001"/>
          <origin xyz="0 0 0"/>
          <inertia ixx="1.0" ixy="0.0" ixz="0.0" iyy="1.0" iyz="0.0" izz="1.0"/>
        </inertial>
        <collision>
          <origin rpy="0 0 0" xyz="0 0 0"/>
          <geometry>
            <box size="0.25 0.11 0.16"/>
          </geometry>
        </collision>
      </link>
      <joint name="camera_joint" type="fixed">
        <origin rpy="0 0 0" xyz="0.044 0 0.1"/>
        <parent link="robotino_base_link"/>
        <child link="camera_link"/>
      </joint>
      <link name="camera_link">
        <inertial>
          <mass value="0.00001"/>
          <origin xyz="0 0 0"/>
          <inertia ixx="1.0" ixy="0.0" ixz="0.0" iyy="1.0" iyz="0.0" izz="1.0"/>
        </inertial>
        <visual>
          <origin rpy="0 0 0" xyz="0 0 0"/>
          <geometry>
            <mesh filename="package://robot_description/meshes/RobotinoCamera.dae" scale="0.01 0.01 0.01"/>
          </geometry>
        </visual>
      </link>
      <joint name="anglebracketusb_joint" type="fixed">
        <origin rpy="0 0 1.570795" xyz="0.008 0 0.137"/>
        <parent link="robotino_base_link"/>
        <child link="anglebracketusb_link"/>
      </joint>
      <link name="anglebracketusb_link">
        <inertial>
          <mass value="0.00001"/>
          <origin xyz="0 0 0"/>
          <inertia ixx="1.0" ixy="0.0" ixz="0.0" iyy="1.0" iyz="0.0" izz="1.0"/>
        </inertial>
        <visual>
          <origin rpy="0 0 0" xyz="0 0 0"/>
          <geometry>
            <mesh filename="package://robot_description/meshes/AngleBracketUSBHub.dae" scale="0.01 0.01 0.01"/>
          </geometry>
        </visual>
      </link>
      <joint name="laser_joint" type="fixed">
        <origin rpy="0 0 0" xyz="-0.022 0 0.232"/>
        <parent link="robotino_base_link"/>
        <child link="laser_link"/>
      </joint>
      <link name="laser_link">
        <inertial>
          <mass value="0.00001"/>
          <origin xyz="0 0 0"/>
          <inertia ixx="1.0" ixy="0.0" ixz="0.0" iyy="1.0" iyz="0.0" izz="1.0"/>
        </inertial>
        <visual>
          <origin rpy="0 0 1.570795" xyz="0 0 0"/>
          <geometry>
            <mesh filename="package://robot_description/meshes/RobotinoLaserScanner.dae" scale="0.01 0.01 0.01"/>
          </geometry>
        </visual>
        <collision>
          <origin rpy="0 0 0" xyz="0 0 0.035"/>
          <geometry>
            <cylinder length="0.07" radius="0.02"/>
          </geometry>
        </collision>
      </link>
      <gazebo reference="laser_link">
        <sensor type="ray" name="head_hokuyo_sensor">
          <pose>0 0 0 0 0 0</pose>
          <visualize>true</visualize>
          <update_rate>40</update_rate>
          <ray>
            <scan>
              <horizontal>
                <samples>720</samples>
                <resolution>1</resolution>
                <min_angle>-1.570796</min_angle>
                <max_angle>1.570796</max_angle>
              </horizontal>
            </scan>
            <range>
              <min>0.10</min>
              <max>30.0</max>
              <resolution>0.01</resolution>
            </range>
            <noise>
              <type>gaussian</type>
              <!-- Noise parameters based on published spec for Hokuyo laser
                   achieving "+-30mm" accuracy at range < 10m.  A mean of 0.0m and
                   stddev of 0.01m will put 99.7% of samples within 0.03m of the true
                   reading. -->
              <mean>0.0</mean>
              <stddev>0.01</stddev>
            </noise>
          </ray>
          <plugin name="gazebo_ros_head_hokuyo_controller" filename="libgazebo_ros_laser.so">
            <topicName>base_scan</topicName>
            <frameName>laser_link</frameName>
          </plugin>
        </sensor>
      </gazebo>
    <gazebo>
        <plugin name="object_controller" filename="libgazebo_ros_planar_move.so">
          <commandTopic>cmd_vel</commandTopic>
          <odometryTopic>odom</odometryTopic>
          <odometryFrame>odom</odometryFrame>
          <odometryRate>20.0</odometryRate>
          <robotBaseFrame>robotino_base_link</robotBaseFrame>
        </plugin>
      </gazebo>
      
        <gazebo reference="camera_link">        
       <sensor type="ray" name="sonar">
          <pose>0 0 0 0 0 0</pose>
          <visualize>true</visualize>
          <update_rate>50</update_rate>
          <ray>
             <scan>
                <horizontal>
                   <samples>10</samples>
                   <resolution>1</resolution> 
                   <min_angle>-0.14835</min_angle>
                   <max_angle>0.14835</max_angle>
                </horizontal>
                <vertical>
                   <samples>10</samples>
                   <resolution>1</resolution> 
                   <min_angle>-0.1</min_angle>
                   <max_angle>0.1</max_angle> 
                </vertical>
             </scan>
             <range>
                <min>0.07</min>
                <max>1</max>
                <resolution>0.02</resolution>
             </range>
          </ray>
          <plugin filename="libgazebo_ros_range.so" name="gazebo_ros_range">
             <gaussianNoise>0.005</gaussianNoise>
             <alwaysOn>true</alwaysOn>
             <updateRate>50</updateRate>
             <topicName>sensor/sonar</topicName>
             <frameName>base_sonar</frameName>
             <radiation>ULTRASOUND</radiation>
             <fov>0.2967</fov>
          </plugin>
       </sensor>  
       </gazebo>


    <!--MODROB parts-->
    <link name="modrob_robotino_base_link" />

    <link name="part1">

        <inertial>
            <origin rpy="0.000000 0.000000 0.000000" xyz="0.000180 0.000130 0.054300" />
            <mass value="2.795000" />
            <inertia ixx="0.014000" ixy="-0.000002" ixz="-0.000003" iyy="0.014000" iyz="0.000005" izz="0.000732" />
        </inertial>

        <visual>
            <origin rpy="0.000000 -0.000000 0.000000" xyz="0.000000 0.000000 0.135300" />
            <geometry>
                <mesh filename="package://modrob_resources/stl_files/MXL.STL" />
            </geometry>
            <material name="color-1">
                <color rgba="0.100000 0.100000 0.500000 1.000000" />
            </material>
        </visual>
        <collision>
            <origin rpy="0.000000 -0.000000 0.000000" xyz="0.000000 0.000000 0.135300" />
            <geometry>
                <mesh filename="package://modrob_resources/stl_files/MXL.STL" />
            </geometry>
        </collision>
    </link>

    <link name="part2">
        <inertial>
            <origin rpy="0.000000 0.000000 0.000000" xyz="0.000630 0.000190 -0.009660" />
            <mass value="0.588000" />
            <inertia ixx="0.000840" ixy="0.000000" ixz="-0.000011" iyy="0.000833" iyz="-0.000001" izz="0.000732" />
        </inertial>
    </link>

    <link name="part3">
        <inertial>
            <origin rpy="0.000000 0.000000 0.000000" xyz="0.000200 -0.036560 0.054520" />
            <mass value="0.581910" />
            <inertia ixx="0.004886" ixy="-0.000007" ixz="0.000007" iyy="0.003453" iyz="-0.001714" izz="0.000000" />
        </inertial>
        <visual>
            <origin rpy="2.356194 -1.570796 2.356194" xyz="0.000000 -0.065500 0.100900" />
            <geometry>
                <mesh filename="package://modrob_resources/stl_files/L_Rasmus_01_90_LL.STL" />
            </geometry>
            <material name="color-3">
                <color rgba="1.000000 1.000000 1.000000 1.000000" />
            </material>
        </visual>
        <collision>
            <origin rpy="2.356194 -1.570796 2.356194" xyz="0.000000 -0.065500 0.100900" />
            <geometry>
                <mesh filename="package://modrob_resources/stl_files/L_Rasmus_01_90_LL.STL" />
            </geometry>
        </collision>
    </link>

    <link name="part4">
        <inertial>
            <origin rpy="0.000000 0.000000 0.000000" xyz="0.000180 0.000130 0.054300" />
            <mass value="2.795000" />
            <inertia ixx="0.014000" ixy="-0.000002" ixz="-0.000003" iyy="0.014000" iyz="0.000005" izz="0.000732" />
        </inertial>
        <visual>
            <origin rpy="0.000000 -0.000000 0.000000" xyz="0.000000 0.000000 0.135300" />
            <geometry>
                <mesh filename="package://modrob_resources/stl_files/MXL+90.STL" />
            </geometry>
            <material name="color-4">
                <color rgba="0.100000 0.100000 0.500000 1.000000" />
            </material>
        </visual>
        <collision>
            <origin rpy="0.000000 -0.000000 0.000000" xyz="0.000000 0.000000 0.135300" />
            <geometry>
                <mesh filename="package://modrob_resources/stl_files/MXL+90.STL" />
            </geometry>
        </collision>
    </link>

    <link name="part5">
        <inertial>
            <origin rpy="0.000000 0.000000 0.000000" xyz="0.000630 0.000190 -0.009660" />
            <mass value="0.588000" />
            <inertia ixx="0.000840" ixy="0.000000" ixz="-0.000011" iyy="0.000833" iyz="-0.000001" izz="0.000732" />
        </inertial>
    </link>

    <link name="part6">
        <inertial>
            <origin rpy="0.000000 0.000000 0.000000" xyz="0.199960 0.000005 0.044435" />
            <mass value="1.615669" />
            <inertia ixx="0.005724" ixy="0.000002" ixz="0.014380" iyy="0.098655" iyz="0.000001" izz="0.000000" />
        </inertial>

        <visual>
            <origin rpy="-0.000000 -3.141593 0.000000" xyz="-0.000000 0.400000 0.000000" />
            <geometry>
                <mesh filename="package://modrob_resources/stl_files/L_360_400_LL_actual.STL" />
            </geometry>
            <material name="color-6">
                <color rgba="1.000000 1.000000 1.000000 1.000000" />
            </material>
        </visual>
        <collision>
            <origin rpy="-0.000000 -3.141593 0.000000" xyz="-0.000000 0.400000 0.000000" />
            <geometry>
                <mesh filename="package://modrob_resources/stl_files/L_360_400_LL_actual.STL" />
            </geometry>
        </collision>
    </link>

    <link name="part7">
        <inertial>
            <origin rpy="0.000000 0.000000 0.000000" xyz="0.000025 0.001030 0.050400" />
            <mass value="2.139300" />
            <inertia ixx="0.009000" ixy="0.000002" ixz="-0.000002" iyy="0.008000" iyz="0.000024" izz="0.000564" />
        </inertial>

        <visual>
            <origin rpy="0.000000 -0.000000 0.000000" xyz="0.000000 0.000000 0.127600" />
            <geometry>
                <mesh filename="package://modrob_resources/stl_files/ML.STL" />
            </geometry>
            <material name="color-7">
                <color rgba="0.100000 0.100000 0.500000 1.000000" />
            </material>
        </visual>
        <collision>
            <origin rpy="0.000000 -0.000000 0.000000" xyz="0.000000 0.000000 0.127600" />
            <geometry>
                <mesh filename="package://modrob_resources/stl_files/ML.STL" />
            </geometry>
        </collision>
    </link>

    <link name="part8">
        <inertial>
            <origin rpy="0.000000 0.000000 0.000000" xyz="-0.000030 0.000010 -0.015900" />
            <mass value="0.473600" />
            <inertia ixx="0.000536" ixy="-0.000000" ixz="-0.000000" iyy="0.000536" iyz="0.000000" izz="0.000564" />
        </inertial>
    </link>

    <link name="part9">
        <inertial>
            <origin rpy="0.000000 0.000000 0.000000" xyz="0.060011 0.005268 0.039688" />
            <mass value="0.578517" />
            <inertia ixx="0.002063" ixy="0.000340" ixz="0.001596" iyy="0.005676" iyz="0.000134" izz="0.000000" />
        </inertial>
        <visual>
            <origin rpy="-1.570796 -0.000000 0.000000" xyz="0.114000 0.047000 0.047000" />
            <geometry>
                <mesh filename="package://modrob_resources/stl_files/L_90S_compact_LL_actual.STL" />
            </geometry>
            <material name="color-9">
                <color rgba="1.000000 1.000000 1.000000 1.000000" />
            </material>
        </visual>
        <collision>
            <origin rpy="-1.570796 -0.000000 0.000000" xyz="0.114000 0.047000 0.047000" />
            <geometry>
                <mesh filename="package://modrob_resources/stl_files/L_90S_compact_LL_actual.STL" />
            </geometry>
        </collision>
    </link>

    <link name="part10">
        <inertial>
            <origin rpy="0.000000 0.000000 0.000000" xyz="0.000025 0.001030 0.050400" />
            <mass value="2.139300" />
            <inertia ixx="0.009000" ixy="0.000002" ixz="-0.000002" iyy="0.008000" iyz="0.000024" izz="0.000564" />
        </inertial>

        <visual>
            <origin rpy="0.000000 -0.000000 0.000000" xyz="0.000000 0.000000 0.127600" />
            <geometry>
                <mesh filename="package://modrob_resources/stl_files/ML.STL" />
            </geometry>
            <material name="color-10">
                <color rgba="0.100000 0.100000 0.500000 1.000000" />
            </material>
        </visual>
        <collision>
            <origin rpy="0.000000 -0.000000 0.000000" xyz="0.000000 0.000000 0.127600" />
            <geometry>
                <mesh filename="package://modrob_resources/stl_files/ML.STL" />
            </geometry>
        </collision>
    </link>

    <link name="part11">
        <inertial>
            <origin rpy="0.000000 0.000000 0.000000" xyz="-0.000030 0.000010 -0.015900" />
            <mass value="0.473600" />
            <inertia ixx="0.000536" ixy="-0.000000" ixz="-0.000000" iyy="0.000536" iyz="0.000000" izz="0.000564" />
        </inertial>
    </link>

    <link name="part12">
        <inertial>
            <origin rpy="0.000000 0.000000 0.000000" xyz="0.000006 0.091445 0.125960" />
            <mass value="1.677416" />
            <inertia ixx="0.107697" ixy="0.000001" ixz="0.000003" iyy="0.091364" iyz="0.034625" izz="0.000000" />
        </inertial>
        <visual>
            <origin rpy="1.570796 -0.000000 0.000000" xyz="0.000000 0.065000 0.250000" />
            <geometry>
                <mesh filename="package://modrob_resources/stl_files/L_90L_250_LS_actual.STL" />
            </geometry>
            <material name="color-12">
                <color rgba="1.000000 1.000000 1.000000 1.000000" />
            </material>
        </visual>
        <collision>
            <origin rpy="1.570796 -0.000000 0.000000" xyz="0.000000 0.065000 0.250000" />
            <geometry>
                <mesh filename="package://modrob_resources/stl_files/L_90L_250_LS_actual.STL" />
            </geometry>
        </collision>
    </link>

    <link name="part13">
        <inertial>
            <origin rpy="0.000000 0.000000 0.000000" xyz="0.000610 0.000080 0.047140" />
            <mass value="1.253380" />
            <inertia ixx="0.004000" ixy="0.000000" ixz="0.000016" iyy="0.005000" iyz="-0.000000" izz="0.000192" />
        </inertial>

        <visual>
            <origin rpy="0.000000 -0.000000 0.000000" xyz="0.000000 0.000000 0.119550" />
            <geometry>
                <mesh filename="package://modrob_resources/stl_files/MS.STL" />
            </geometry>
            <material name="color-13">
                <color rgba="0.100000 0.100000 0.500000 1.000000" />
            </material>
        </visual>
        <collision>
            <origin rpy="0.000000 -0.000000 0.000000" xyz="0.000000 0.000000 0.119550" />
            <geometry>
                <mesh filename="package://modrob_resources/stl_files/MS.STL" />
            </geometry>
        </collision>
    </link>
    
    <link name="part14">
        <inertial>
            <origin rpy="0.000000 0.000000 0.000000" xyz="-0.000044 -0.000008 -0.001115" />
            <mass value="0.289400" />
            <inertia ixx="0.000178" ixy="-0.000000" ixz="-0.000000" iyy="0.000178" iyz="0.000000" izz="0.000192" />
        </inertial>
    </link>

    <link name="part15">
        <inertial>
            <origin rpy="0.000000 0.000000 0.000000" xyz="-0.043600 0.035200 -0.023740" />
            <mass value="0.337890" />
            <inertia ixx="0.001553" ixy="-0.000777" ixz="0.000685" iyy="0.001824" iyz="-0.000526" izz="0.000000" />
        </inertial>

        <visual>
            <origin rpy="1.570796 3.141593 1.570796" xyz="-0.060000 0.063000 -0.058000" />
            <geometry>
                <mesh filename="package://modrob_resources/stl_files/L_Rasmus_02_90_SS.STL" />
            </geometry>
            <material name="color-15">
                <color rgba="1.000000 1.000000 1.000000 1.000000" />
            </material>
        </visual>
        <collision>
            <origin rpy="1.570796 3.141593 1.570796" xyz="-0.060000 0.063000 -0.058000" />
            <geometry>
                <mesh filename="package://modrob_resources/stl_files/L_Rasmus_02_90_SS.STL" />
            </geometry>
        </collision>
    </link>

    <link name="part16">
        <inertial>
            <origin rpy="0.000000 0.000000 0.000000" xyz="0.000610 0.000080 0.047140" />
            <mass value="1.253380" />
            <inertia ixx="0.004000" ixy="0.000000" ixz="0.000016" iyy="0.005000" iyz="-0.000000" izz="0.000192" />
        </inertial>

        <visual>
            <origin rpy="0.000000 -0.000000 0.000000" xyz="0.000000 0.000000 0.119550" />
            <geometry>
                <mesh filename="package://modrob_resources/stl_files/MS.STL" />
            </geometry>
            <material name="color-16">
                <color rgba="0.100000 0.100000 0.500000 1.000000" />
            </material>
        </visual>
        <collision>
            <origin rpy="0.000000 -0.000000 0.000000" xyz="0.000000 0.000000 0.119550" />
            <geometry>
                <mesh filename="package://modrob_resources/stl_files/MS.STL" />
            </geometry>
        </collision>
    </link>

    <link name="part17">
        <inertial>
            <origin rpy="0.000000 0.000000 0.000000" xyz="-0.000044 -0.000008 -0.001115" />
            <mass value="0.289400" />
            <inertia ixx="0.000178" ixy="-0.000000" ixz="-0.000000" iyy="0.000178" iyz="0.000000" izz="0.000192" />
        </inertial>
    </link>

    <link name="hand">

        <inertial>
            <origin rpy="0.000000 0.0 0.000000" xyz="0.000000 0.000000 0.06250" />
            <mass value="0.184000" />
            <inertia ixx="0.550000" ixy="-0.000002" ixz="-0.000003" iyy="0.930000" iyz="0.000005" izz="0.550000" />
        </inertial>

        <visual>
            <origin rpy="0.000000 -0.000000 0.000000" xyz="0.000000 0.000000 0.06250" />
            <geometry>
                <mesh filename="package://modrob_resources/stl_files/E_Schimaneck.STL" />
            </geometry>
        </visual>
        <collision>
            <origin rpy="0.000000 -0.000000 0.000000" xyz="0.000000 0.000000 0.062500" />
            <geometry>
                <mesh filename="package://modrob_resources/stl_files/E_Schimaneck.STL" />
            </geometry>
        </collision>
    </link>
    <gazebo reference="hand">
        <material>Gazebo/DarkGrey</material>
        <selfCollide>true</selfCollide>
    </gazebo>
    <gazebo reference="hand">
        <kp>110.0</kp>
        <kd>10.0</kd>
        <mu1>100.000000</mu1>
        <mu2>100.000000</mu2>
    </gazebo>
    <link name="finger1">

        <inertial>
            <origin rpy="0.00000 0.000000 0.0" xyz="0.0 -0.000 0.001500" />
            <mass value="0.006944" />
            <inertia ixx="0.000004629" ixy="0.000000486" ixz="0.000000972" iyy="0.000004157" iyz="0.000001389" izz="0.00000138" />
        </inertial>

        <visual>
            <origin rpy="0.000000 0.000000 0.0" xyz="0.0 -0.000 0.001500" />
            <geometry>
                <mesh filename="package://robot_description/meshes/finger_Birne_Gimatic_m.STL" />
            </geometry>
        </visual>
        <collision>
            <origin rpy="0.000000 0.000000 0.0" xyz="0.0 -0.000 0.001500" />
            <geometry>
                <mesh filename="package://robot_description/meshes/finger_Birne_Gimatic_m.STL" />
            </geometry>
        </collision>
    </link>
    <gazebo reference="finger1">
        <material>Gazebo/Blue</material>
    </gazebo>
    <gazebo reference="finger1">
        <kp>10000.000000</kp>
        <kd>10.000000</kd>
        <mu1>100.00</mu1>
        <!-- was 0.38-->
        <mu2>100.00</mu2>
    </gazebo>
    <link name="finger2">

        <inertial>
            <origin rpy="0.00000 0.000000 0.0" xyz="0.000 0.00 0.001500" />
            <mass value="0.006944" />
            <inertia ixx="0.000004629" ixy="0.000000486" ixz="0.000000972" iyy="0.000004157" iyz="0.000001389" izz="0.00000138" />
        </inertial>

        <visual>
            <origin rpy="0.000000 0.000000 0.0" xyz="0.000 0.00 0.001500" />
            <geometry>
                <mesh filename="package://robot_description/meshes/finger_Birne_Gimatic_m.STL" />
            </geometry>
        </visual>
        <collision>
            <origin rpy="0.000000 0.000000 0.0" xyz="0.000 0.00 0.001500" />
            <geometry>
                <mesh filename="package://robot_description/meshes/finger_Birne_Gimatic_m.STL" />
            </geometry>
        </collision>
    </link>
    <gazebo reference="finger2">
        <material>Gazebo/Blue</material>
    </gazebo>
    <gazebo reference="finger1">
        <kp>10000.000000</kp>
        <kd>10.000000</kd>
        <mu1>100.00</mu1>
        <mu2>100.00</mu2>
    </gazebo>
    <!-- End of links-->
    <!-- MODROB JOINTS-->
    <joint name="base_part1" type="fixed">
        <origin xyz="0.000000 0.000000 0.100000" rpy="0.000000 -0.000000 0.000000" />
        <parent link="modrob_robotino_base_link" />
        <child link="part1" />
        <axis xyz="0.000000 0.000000 0.000000" />
    </joint>
    <joint name="part2_part3" type="fixed">
        <origin xyz="0.000000 0.000000 0.067650" rpy="0.000000 -0.000000 0.000000" />
        <parent link="part2" />
        <child link="part3" />
        <axis xyz="0.000000 0.000000 0.000000" />
    </joint>
    <joint name="joint0" type="revolute">
        <origin xyz="0.000000 0.000000 0.067650" rpy="0.000000 -0.000000 0.000000" />
        <parent link="part1" />
        <child link="part2" />
        <axis xyz="0.000000 0.000000 1.000000" />
        <limit effort="0.000000" velocity="0.000000" lower="-3.141593" upper="3.141593" />
    </joint>
    <joint name="part3_part4" type="fixed">
        <origin xyz="0.000000 -0.065500 0.100900" rpy="2.356194 -1.570796 2.356194" />
        <parent link="part3" />
        <child link="part4" />
        <axis xyz="0.000000 0.000000 0.000000" />
    </joint>
    <joint name="part5_part6" type="fixed">
        <origin xyz="0.000000 0.000000 0.067650" rpy="0.000000 -0.000000 0.000000" />
        <parent link="part5" />
        <child link="part6" />
        <axis xyz="0.000000 0.000000 0.000000" />
    </joint>
    <joint name="joint1" type="revolute">
        <origin xyz="0.000000 0.000000 0.067650" rpy="0.0 0.000000 -2.0944 " />
        <parent link="part4" />
        <child link="part5" />
        <axis xyz="0.000000 0.000000 1.000000" />
        <limit effort="0.000000" velocity="0.000000" lower="-3.141593" upper="3.141593" />
    </joint>
    <joint name="part6_part7" type="fixed">
        <origin xyz="-0.000000 0.400000 0.000000" rpy="-0.000000 -3.141593 0.000000" />
        <parent link="part6" />
        <child link="part7" />
        <axis xyz="0.000000 0.000000 0.000000" />
    </joint>
    <joint name="part8_part9" type="fixed">
        <origin xyz="0.000000 0.000000 0.063800" rpy="0.000000 -0.000000 0.000000" />
        <parent link="part8" />
        <child link="part9" />
        <axis xyz="0.000000 0.000000 0.000000" />
    </joint>
    <joint name="joint2" type="revolute">
        <origin xyz="0.000000 0.000000 0.063800" rpy="0.000000 -0.000000 -2.0944" />
        <parent link="part7" />
        <child link="part8" />
        <axis xyz="0.000000 0.000000 1.000000" />
        <limit effort="0.000000" velocity="0.000000" lower="-3.141593" upper="3.141593" />
    </joint>
    <joint name="part9_part10" type="fixed">
        <origin xyz="0.114000 0.047000 0.047000" rpy="-1.570796 -0.000000 0.000000" />
        <parent link="part9" />
        <child link="part10" />
        <axis xyz="0.000000 0.000000 0.000000" />
    </joint>
    <joint name="part11_part12" type="fixed">
        <origin xyz="0.000000 0.000000 0.063800" rpy="0.000000 -0.000000 0.000000" />
        <parent link="part11" />
        <child link="part12" />
        <axis xyz="0.000000 0.000000 0.000000" />
    </joint>
    <joint name="joint3" type="revolute">
        <origin xyz="0.000000 0.000000 0.063800" rpy="0.000000 -0.000000 0.000000" />
        <parent link="part10" />
        <child link="part11" />
        <axis xyz="0.000000 0.000000 1.000000" />
        <limit effort="0.000000" velocity="0.000000" lower="-3.141593" upper="3.141593" />
    </joint>
    <joint name="part12_part13" type="fixed">
        <origin xyz="0.000000 0.065000 0.250000" rpy="1.570796 -0.000000 0.000000" />
        <parent link="part12" />
        <child link="part13" />
        <axis xyz="0.000000 0.000000 0.000000" />
    </joint>
    <joint name="part14_part15" type="fixed">
        <origin xyz="0.000000 0.000000 0.059775" rpy="0.000000 -0.000000 0.000000" />
        <parent link="part14" />
        <child link="part15" />
        <axis xyz="0.000000 0.000000 0.000000" />
    </joint>
    <joint name="joint4" type="revolute">
        <origin xyz="0.000000 0.000000 0.059775" rpy="0.000000 -0.000000 1.5708" />
        <parent link="part13" />
        <child link="part14" />
        <axis xyz="0.000000 0.000000 1.000000" />
        <limit effort="0.000000" velocity="0.000000" lower="-3.141593" upper="3.141593" />
    </joint>
    <joint name="part15_part16" type="fixed">
        <origin xyz="-0.060000 0.063000 -0.058000" rpy="1.570796 3.141593 1.570796" />
        <parent link="part15" />
        <child link="part16" />
        <axis xyz="0.000000 0.000000 0.000000" />
    </joint>
    <joint name="part17_hand" type="fixed">
        <origin xyz="0.000000 0.000000 0.1" rpy="0.000000 -0.000000 0.000000" />
        <parent link="part17" />
        <child link="hand" />
        <axis xyz="0.000000 0.000000 0.000000" />
    </joint>
    <joint name="joint5" type="revolute">
        <origin xyz="0.000000 0.000000 0.059775" rpy="0.000000 -0.000000 0.000000" />
        <parent link="part16" />
        <child link="part17" />
        <axis xyz="0.000000 0.000000 1.000000" />
        <limit effort="0.000000" velocity="0.000000" lower="-3.141593" upper="3.141593" />
    </joint>

    <joint name="hand_to_finger1" type="prismatic">
        <origin rpy="0.000000 0.000000 +1.570796327" xyz="0.00700 -0.02980 0.06200" />
        <!-- xyz="0.00700 -0.03200 0.06200" -->
        <parent link="hand" />
        <child link="finger1" />
        <dynamics damping="12.590000" friction="0.400000" />
        <limit effort="3.0" lower="-0.0" upper="0.0100" velocity="0.5" />
        <!-- was 0.38 and 0.0 -->
    </joint>
    <joint name="hand_to_finger2" type="prismatic">
        <origin rpy="0.000000 0.000000 -1.570796327" xyz="-0.00700 0.0580 0.06200" />
        <!--- xyz="-0.00700 0.0620 0.06200" -->
        <parent link="hand" />
        <child link="finger2" />
        <dynamics damping="12.590000" friction="0.400000" />
        <limit effort="3.0" lower="0.03" upper="0.04" velocity="0.5" />
    </joint>
    <!-- End of joints-->
    <!-- MODROB transmissions-->
    <transmission name="trans_hand_to_finger1">
        <type>transmission_interface/SimpleTransmission</type>
        <joint name="hand_to_finger1">
            <hardwareInterface>hardware_interface/EffortJointInterface</hardwareInterface>
        </joint>
        <actuator name="motor_hand_to_finger1">
            <mechanicalReduction>160</mechanicalReduction>
        </actuator>
    </transmission>
    <transmission name="trans_hand_to_finger2">
        <type>transmission_interface/SimpleTransmission</type>
        <joint name="hand_to_finger2">
            <hardwareInterface>hardware_interface/EffortJointInterface</hardwareInterface>
        </joint>
        <actuator name="motor_hand_to_finger2">
            <mechanicalReduction>160</mechanicalReduction>
        </actuator>
    </transmission>

    <transmission name="trans5">
        <type>transmission_interface/SimpleTransmission</type>
        <joint name="joint5">
            <hardwareInterface>hardware_interface/EffortJointInterface</hardwareInterface>
        </joint>
        <actuator name="motor5">
            <mechanicalReduction>120.000000</mechanicalReduction>
        </actuator>
    </transmission>
    <transmission name="trans4">
        <type>transmission_interface/SimpleTransmission</type>
        <joint name="joint4">
            <hardwareInterface>hardware_interface/EffortJointInterface</hardwareInterface>
        </joint>
        <actuator name="motor4">
            <mechanicalReduction>120.000000</mechanicalReduction>
        </actuator>
    </transmission>
    <transmission name="trans3">
        <type>transmission_interface/SimpleTransmission</type>
        <joint name="joint3">
            <hardwareInterface>hardware_interface/EffortJointInterface</hardwareInterface>
        </joint>
        <actuator name="motor3">
            <mechanicalReduction>120.000000</mechanicalReduction>
        </actuator>
    </transmission>
    <transmission name="trans2">
        <type>transmission_interface/SimpleTransmission</type>
        <joint name="joint2">
            <hardwareInterface>hardware_interface/EffortJointInterface</hardwareInterface>
        </joint>
        <actuator name="motor2">
            <mechanicalReduction>160.000000</mechanicalReduction>
        </actuator>
    </transmission>
    <transmission name="trans1">
        <type>transmission_interface/SimpleTransmission</type>
        <joint name="joint1">
            <hardwareInterface>hardware_interface/EffortJointInterface</hardwareInterface>
        </joint>
        <actuator name="motor1">
            <mechanicalReduction>160.000000</mechanicalReduction>
        </actuator>
    </transmission>
    <transmission name="trans0">
        <type>transmission_interface/SimpleTransmission</type>
        <joint name="joint0">
            <hardwareInterface>hardware_interface/EffortJointInterface</hardwareInterface>
        </joint>
        <actuator name="motor0">
            <mechanicalReduction>160.000000</mechanicalReduction>
        </actuator>
    </transmission>
    <!-- End of modrob transmissions-->
    <!-- Base link-->
    <joint name="base_to_robotino_joint" type="fixed">
        <parent link="base_link" />
        <child link="robotino_base_link" />
        <origin xyz="0 0 0" />
    </joint>
    <!-- joint between modrob and the robotino base-->
    <joint name="modrob_to_robotino_joint" type="fixed">
        <parent link="robotino_base_link" />
        <child link="modrob_robotino_base_link" />
        <origin xyz="-0.1 0 0.2" />
    </joint>

    <!--REALSENSE ENDEFFECTOR CAMERA-->
    <material name="camera_d415_aluminum">
        <color rgba="0.5 0.5 0.5 1" />
    </material>
    <!-- camera body, with origin at bottom screw mount -->
    <joint name="camera_d415_joint" type="fixed">
        <origin rpy="3.14159 -1.5708 0.0" xyz="0.03 -0.005 -0.005" />
        <parent link="hand" />
        <child link="camera_d415_bottom_screw_frame" />
    </joint>
    <link name="camera_d415_bottom_screw_frame" />
    <joint name="camera_d415_link_joint" type="fixed">
        <origin rpy="0 0 0" xyz="0 0.02 0.0115" />
        <parent link="camera_d415_bottom_screw_frame" />
        <child link="camera_d415_link" />
    </joint>
    <link name="camera_d415_link">
        <visual>
            <origin rpy="1.57079632679 0 1.57079632679" xyz="0.00987 -0.02 0" />
            <geometry>
                <mesh filename="package://robot_description/meshes/d415.stl" />
            </geometry>
            <material name="camera_d415_aluminum" />
        </visual>
        <collision>
            <origin rpy="0 0 0" xyz="0 -0.02 0" />
            <geometry>
                <box size="0.02005 0.099 0.023" />
            </geometry>
        </collision>

        <inertial>
            <!-- The following are not reliable values, and should not be used for modeling -->
            <mass value="0.564" />
            <origin xyz="0 0 0" />
            <inertia ixx="0.003881243" ixy="0.0" ixz="0.0" iyy="0.000498940" iyz="0.0" izz="0.003879257" />
        </inertial>

    </link>
    <!-- camera depth joints and links -->
    <joint name="camera_d415_depth_joint" type="fixed">
        <origin rpy="0 0 0" xyz="0 0 0" />
        <parent link="camera_d415_link" />
        <child link="camera_d415_depth_frame" />
    </joint>
    <link name="camera_d415_depth_frame" />
    <joint name="camera_d415_depth_optical_joint" type="fixed">
        <origin rpy="-1.57079632679 0 -1.57079632679" xyz="0 0 0" />
        <parent link="camera_d415_depth_frame" />
        <child link="camera_d415_depth_optical_frame" />
    </joint>
    <link name="camera_d415_depth_optical_frame" />
    <!-- camera left IR joints and links -->
    <joint name="camera_d415_left_ir_joint" type="fixed">
        <origin rpy="0 0 0" xyz="0 0.0 0" />
        <parent link="camera_d415_depth_frame" />
        <child link="camera_d415_left_ir_frame" />
    </joint>
    <link name="camera_d415_left_ir_frame" />
    <joint name="camera_d415_left_ir_optical_joint" type="fixed">
        <origin rpy="-1.57079632679 0 -1.57079632679" xyz="0 0 0" />
        <parent link="camera_d415_left_ir_frame" />
        <child link="camera_d415_left_ir_optical_frame" />
    </joint>
    <link name="camera_d415_left_ir_optical_frame" />
    <!-- camera right IR joints and links -->
    <joint name="camera_d415_right_ir_joint" type="fixed">
        <origin rpy="0 0 0" xyz="0 -0.055 0" />
        <parent link="camera_d415_depth_frame" />
        <child link="camera_d415_right_ir_frame" />
    </joint>
    <link name="camera_d415_right_ir_frame" />
    <joint name="camera_d415_right_ir_optical_joint" type="fixed">
        <origin rpy="-1.57079632679 0 -1.57079632679" xyz="0 0 0" />
        <parent link="camera_d415_right_ir_frame" />
        <child link="camera_d415_right_ir_optical_frame" />
    </joint>
    <link name="camera_d415_right_ir_optical_frame" />
    <!-- camera color joints and links -->
    <joint name="camera_d415_color_joint" type="fixed">
        <origin rpy="0 0 0" xyz="0 0.015 0" />
        <parent link="camera_d415_depth_frame" />
        <child link="camera_d415_color_frame" />
    </joint>
    <link name="camera_d415_color_frame" />
    <joint name="camera_d415_color_optical_joint" type="fixed">
        <origin rpy="-1.57079632679 0 -1.57079632679" xyz="0 0 0" />
        <parent link="camera_d415_color_frame" />
        <child link="camera_d415_color_optical_frame" />
    </joint>
    <link name="camera_d415_color_optical_frame" />
    <!-- Camera gazebo references-->
    <gazebo reference="camera_d415_bottom_screw_frame">
        <self_collide>0</self_collide>
        <enable_wind>0</enable_wind>
        <kinematic>0</kinematic>
        <gravity>1</gravity>
        <mu2>1</mu2>
        <fdir1>0 0 0</fdir1>
        <kp>1e+13</kp>
        <kd>1</kd>
        <sensor name="camera_d415_color" type="camera">
            <plugin name="lab_robot_camera" filename="librealsense_gazebo_plugin.so">
                <prefix>lab_robot</prefix>
                <depthUpdateRate>60.0</depthUpdateRate>
                <colorUpdateRate>60.0</colorUpdateRate>
                <infraredUpdateRate>60.0</infraredUpdateRate>
                <depthTopicName>depth/image_raw</depthTopicName>
                <depthCameraInfoTopicName>depth/camera_info</depthCameraInfoTopicName>
                <colorTopicName>color/image_raw</colorTopicName>
                <colorCameraInfoTopicName>color/camera_info</colorCameraInfoTopicName>
                <infrared1TopicName>infra1/image_raw</infrared1TopicName>
                <infrared1CameraInfoTopicName>infra1/camera_info</infrared1CameraInfoTopicName>
                <infrared2TopicName>infra2/image_raw</infrared2TopicName>
                <infrared2CameraInfoTopicName>infra2/camera_info</infrared2CameraInfoTopicName>
                <colorOpticalframeName>camera_d415_color_frame</colorOpticalframeName>
                <depthOpticalframeName>camera_d415_depth_frame</depthOpticalframeName>
                <infrared1OpticalframeName>camera_d415_right_ir_frame</infrared1OpticalframeName>
                <infrared2OpticalframeName>camera_d415_left_ir_frame</infrared2OpticalframeName>
                <rangeMinDepth>0.2</rangeMinDepth>
                <rangeMaxDepth>10.0</rangeMaxDepth>
                <pointCloud>true</pointCloud>
                <pointCloudTopicName>depth/points</pointCloudTopicName>
                <pointCloudCutoff>0.5</pointCloudCutoff>
            </plugin>
            <camera name="camera_d415">
                <horizontal_fov>1.21125850088</horizontal_fov>
                <image>
                    <width>1920</width>
                    <height>1080</height>
                    <format>RGB_INT8</format>
                </image>
                <clip>
                    <near>0.1</near>
                    <far>100</far>
                </clip>
                <noise>
                    <type>gaussian</type>
                    <mean>0.0</mean>
                    <stddev>0.007</stddev>
                </noise>
            </camera>
            <always_on>1</always_on>
            <update_rate>30</update_rate>
            <visualize>1</visualize>
        </sensor>
        <sensor name="camera_d415_ired1" type="camera">
            <camera name="camera_d415">
                <horizontal_fov>1.4870205227</horizontal_fov>
                <image>
                    <width>1280</width>
                    <height>720</height>
                    <format>L_INT8</format>
                </image>
                <clip>
                    <near>0.1</near>
                    <far>100</far>
                </clip>
                <noise>
                    <type>gaussian</type>
                    <mean>0.0</mean>
                    <stddev>0.05</stddev>
                </noise>
            </camera>
            <always_on>1</always_on>
            <update_rate>90</update_rate>
            <visualize>0</visualize>
        </sensor>
        <sensor name="camera_d415_ired2" type="camera">
            <camera name="camera_d415">
                <horizontal_fov>1.4870205227</horizontal_fov>
                <image>
                    <width>1280</width>
                    <height>720</height>
                    <format>L_INT8</format>
                </image>
                <clip>
                    <near>0.1</near>
                    <far>100</far>
                </clip>
                <noise>
                    <type>gaussian</type>
                    <mean>0.0</mean>
                    <stddev>0.05</stddev>
                </noise>
            </camera>
            <always_on>1</always_on>
            <update_rate>90</update_rate>
            <visualize>0</visualize>
        </sensor>
        <sensor name="camera_d415_depth" type="depth">
            <camera name="camera_d415">
                <horizontal_fov>1.4870205227</horizontal_fov>
                <image>
                    <width>1280</width>
                    <height>720</height>
                </image>
                <clip>
                    <near>0.1</near>
                    <far>100</far>
                </clip>
                <noise>
                    <type>gaussian</type>
                    <mean>0.0</mean>
                    <stddev>0.100</stddev>
                </noise>
            </camera>
            <plugin name="camera_plugin" filename="libgazebo_ros_openni_kinect.so">
                <baseline>0.2</baseline>
                <alwaysOn>true</alwaysOn>
                <!-- Keep this zero, update_rate in the parent <sensor> tag
            will control the frame rate. -->
                <updateRate>0.0</updateRate>
                <cameraName>camera_ir</cameraName>
                <imageTopicName>/camera/color/image_raw</imageTopicName>
                <cameraInfoTopicName>/camera/color/camera_info</cameraInfoTopicName>
                <depthImageTopicName>/camera/depth/image_raw</depthImageTopicName>
                <depthImageCameraInfoTopicName>/camera/depth/camera_info</depthImageCameraInfoTopicName>
                <pointCloudTopicName>/camera/depth/points</pointCloudTopicName>
                <frameName>camera_link</frameName>
                <pointCloudCutoff>0.5</pointCloudCutoff>
                <pointCloudCutoffMax>3.0</pointCloudCutoffMax>
                <distortionK1>0</distortionK1>
                <distortionK2>0</distortionK2>
                <distortionK3>0</distortionK3>
                <distortionT1>0</distortionT1>
                <distortionT2>0</distortionT2>
                <CxPrime>0</CxPrime>
                <Cx>0</Cx>
                <Cy>0</Cy>
                <focalLength>0</focalLength>
                <hackBaseline>0</hackBaseline>
            </plugin>
            <always_on>1</always_on>
            <update_rate>90</update_rate>
            <visualize>0</visualize>
        </sensor>
    </gazebo>
    <!-- END OF CAMERA-->
  <!--  <gazebo>
        <plugin name="object_controller" filename="libgazebo_ros_planar_move.so">
            <robotNamespace>/lab_robot</robotNamespace>
            <commandTopic>cmd_vel</commandTopic>
            <odometryTopic>odom</odometryTopic>
            <odometryFrame>odom</odometryFrame>
            <odometryRate>20.0</odometryRate>
            <robotBaseFrame>base_link</robotBaseFrame>
        </plugin>
        <plugin name="gazebo_ros_control" filename="libgazebo_ros_control.so">
            <robotNamespace>/lab_robot</robotNamespace>
        </plugin>
        <plugin filename="libgazebo_ros_moveit_planning_scene.so" name="gazebo_ros_moveit_planning_scene">
            <topicName>/planning_scene</topicName>
            <sceneName>laboratory</sceneName>
            <robotName>lab_robot</robotName>
            <updatePeriod>0.5</updatePeriod>
        </plugin>
    </gazebo>

    <gazebo>
        <plugin name="gazebo_ros_control" filename="libgazebo_ros_control.so">
            <robotNamespace>/</robotNamespace>
        </plugin>
    </gazebo>-->
</robot>